File: homeworks/hw2/enve422_sludge_shear.csv
Sludge Type,Shear Stress (N/m²),Shear Rate (1/s)
S1,3.8,1.8
S1,5.4,3.7
S1,9,7.3
S1,14.1,14.7
S1,23.1,36.7
S1,35.7,73.4
S2,1.7,1.8
S2,3.6,3.7
S2,7.5,7.3
S2,15,14.7
S2,36.9,36.7
S2,74.2,73.4
S3,15.4,1.8
S3,17.3,3.7
S3,21.3,7.3
S3,28.7,14.7
S3,50.6,36.7
S3,87.9,73.4